<?xml version="1.0" ?>
<!-- =================================================================================== -->
<!-- |    This document was autogenerated by xacro from /home/sen/ros/hand_arm_ws/src/allegro_hand_description/panda/panda.urdf.xacro | -->
<!-- |    EDITING THIS FILE BY HAND IS NOT RECOMMENDED                                 | -->
<!-- =================================================================================== -->
<robot name="panda">
    <!-- sub-link defining detailed meshes for collision with environment -->
    <link name="panda_link0">
        <visual>
            <geometry>
                <mesh filename="package://allegro_hand_description/meshes/visual/link0.dae" />
            </geometry>
        </visual>
        <collision>
            <geometry>
                <mesh filename="package://allegro_hand_description/meshes/collision/link0.stl" />
            </geometry>
        </collision>
        <inertial>
            <mass value="0.1" />
            <origin xyz="0 0 0" rpy="0 0 0" />
            <inertia ixx="0.03" iyy="0.03" izz="0.03" ixy="0.0" ixz="0.0" iyz="0.0" />
        </inertial>
    </link>
    <!-- sub-link defining coarse geometries of real robot's internal self-collision -->
    <link name="panda_link0_sc">
        <collision>
            <origin rpy="0 1.5707963267948966 0" xyz="-0.075 0 0.06" />
            <geometry>
                <cylinder length="0.03" radius="0.09" />
            </geometry>
        </collision>
        <collision>
            <origin xyz="-0.06 0 0.06" />
            <geometry>
                <sphere radius="0.09" />
            </geometry>
        </collision>
        <collision>
            <origin xyz="-0.09 0 0.06" />
            <geometry>
                <sphere radius="0.09" />
            </geometry>
        </collision>
        <inertial>
            <mass value="0.1" />
            <origin xyz="0 0 0" rpy="0 0 0" />
            <inertia ixx="0.03" iyy="0.03" izz="0.03" ixy="0.0" ixz="0.0" iyz="0.0" />
        </inertial>
    </link>
    <!-- fixed joint between both sub-links -->
    <joint name="panda_link0_sc_joint" type="fixed">
        <origin rpy="0 0 0" />
        <parent link="panda_link0" />
        <child link="panda_link0_sc" />
    </joint>
    <!-- sub-link defining detailed meshes for collision with environment -->
    <link name="panda_link1">
        <visual>
            <geometry>
                <mesh filename="package://allegro_hand_description/meshes/visual/link1.dae" />
            </geometry>
        </visual>
        <collision>
            <geometry>
                <mesh filename="package://allegro_hand_description/meshes/collision/link1.stl" />
            </geometry>
        </collision>
        <inertial>
            <mass value="0.1" />
            <origin xyz="0 0 0" rpy="0 0 0" />
            <inertia ixx="0.03" iyy="0.03" izz="0.03" ixy="0.0" ixz="0.0" iyz="0.0" />
        </inertial>
    </link>
    <!-- sub-link defining coarse geometries of real robot's internal self-collision -->
    <link name="panda_link1_sc">
        <collision>
            <origin rpy="0 0 0" xyz="0 0 -0.1915" />
            <geometry>
                <cylinder length="0.283" radius="0.09" />
            </geometry>
        </collision>
        <collision>
            <origin xyz="0 0 -0.05000000000000002" />
            <geometry>
                <sphere radius="0.09" />
            </geometry>
        </collision>
        <collision>
            <origin xyz="0 0 -0.33299999999999996" />
            <geometry>
                <sphere radius="0.09" />
            </geometry>
        </collision>
        <inertial>
            <mass value="0.1" />
            <origin xyz="0 0 0" rpy="0 0 0" />
            <inertia ixx="0.03" iyy="0.03" izz="0.03" ixy="0.0" ixz="0.0" iyz="0.0" />
        </inertial>
    </link>
    <!-- fixed joint between both sub-links -->
    <joint name="panda_link1_sc_joint" type="fixed">
        <origin rpy="0 0 0" />
        <parent link="panda_link1" />
        <child link="panda_link1_sc" />
    </joint>
    <joint name="panda_joint1" type="revolute">
        <origin rpy="0 0 0" xyz="0 0 0.333" />
        <parent link="panda_link0" />
        <child link="panda_link1" />
        <axis xyz="0 0 1" />
        <limit effort="87.0" lower="-2.8973" upper="2.8973" velocity="2.175" />
        <safety_controller k_position="100.0" k_velocity="40.0" soft_lower_limit="-2.8973" soft_upper_limit="2.8973" />
        <dynamics D="1" K="7000" damping="0.003" friction="0.0" mu_coulomb="0" mu_viscous="16" />
    </joint>
    <!-- sub-link defining detailed meshes for collision with environment -->
    <link name="panda_link2">
        <visual>
            <geometry>
                <mesh filename="package://allegro_hand_description/meshes/visual/link2.dae" />
            </geometry>
        </visual>
        <collision>
            <geometry>
                <mesh filename="package://allegro_hand_description/meshes/collision/link2.stl" />
            </geometry>
        </collision>
        <inertial>
            <mass value="0.1" />
            <origin xyz="0 0 0" rpy="0 0 0" />
            <inertia ixx="0.03" iyy="0.03" izz="0.03" ixy="0.0" ixz="0.0" iyz="0.0" />
        </inertial>
    </link>
    <!-- sub-link defining coarse geometries of real robot's internal self-collision -->
    <link name="panda_link2_sc">
        <collision>
            <origin rpy="0 0 0" xyz="0 0 0" />
            <geometry>
                <cylinder length="0.12" radius="0.09" />
            </geometry>
        </collision>
        <collision>
            <origin xyz="0 0 0.06" />
            <geometry>
                <sphere radius="0.09" />
            </geometry>
        </collision>
        <collision>
            <origin xyz="0 0 -0.06" />
            <geometry>
                <sphere radius="0.09" />
            </geometry>
        </collision>
        <inertial>
            <mass value="0.1" />
            <origin xyz="0 0 0" rpy="0 0 0" />
            <inertia ixx="0.03" iyy="0.03" izz="0.03" ixy="0.0" ixz="0.0" iyz="0.0" />
        </inertial>
    </link>
    <!-- fixed joint between both sub-links -->
    <joint name="panda_link2_sc_joint" type="fixed">
        <origin rpy="0 0 0" />
        <parent link="panda_link2" />
        <child link="panda_link2_sc" />
    </joint>
    <joint name="panda_joint2" type="revolute">
        <origin rpy="-1.5707963267948966 0 0" xyz="0 0 0" />
        <parent link="panda_link1" />
        <child link="panda_link2" />
        <axis xyz="0 0 1" />
        <limit effort="87.0" lower="-1.7628" upper="1.7628" velocity="2.175" />
        <safety_controller k_position="100.0" k_velocity="40.0" soft_lower_limit="-1.7628" soft_upper_limit="1.7628" />
        <dynamics D="1" K="7000" damping="0.003" friction="0.0" mu_coulomb="0" mu_viscous="16" />
    </joint>
    <!-- sub-link defining detailed meshes for collision with environment -->
    <link name="panda_link3">
        <visual>
            <geometry>
                <mesh filename="package://allegro_hand_description/meshes/visual/link3.dae" />
            </geometry>
        </visual>
        <collision>
            <geometry>
                <mesh filename="package://allegro_hand_description/meshes/collision/link3.stl" />
            </geometry>
        </collision>
        <inertial>
            <mass value="0.1" />
            <origin xyz="0 0 0" rpy="0 0 0" />
            <inertia ixx="0.03" iyy="0.03" izz="0.03" ixy="0.0" ixz="0.0" iyz="0.0" />
        </inertial>
    </link>
    <!-- sub-link defining coarse geometries of real robot's internal self-collision -->
    <link name="panda_link3_sc">
        <collision>
            <origin rpy="0 0 0" xyz="0 0 -0.145" />
            <geometry>
                <cylinder length="0.15" radius="0.09" />
            </geometry>
        </collision>
        <collision>
            <origin xyz="0 0 -0.06999999999999999" />
            <geometry>
                <sphere radius="0.09" />
            </geometry>
        </collision>
        <collision>
            <origin xyz="0 0 -0.21999999999999997" />
            <geometry>
                <sphere radius="0.09" />
            </geometry>
        </collision>
        <inertial>
            <mass value="0.1" />
            <origin xyz="0 0 0" rpy="0 0 0" />
            <inertia ixx="0.03" iyy="0.03" izz="0.03" ixy="0.0" ixz="0.0" iyz="0.0" />
        </inertial>
    </link>
    <!-- fixed joint between both sub-links -->
    <joint name="panda_link3_sc_joint" type="fixed">
        <origin rpy="0 0 0" />
        <parent link="panda_link3" />
        <child link="panda_link3_sc" />
    </joint>
    <joint name="panda_joint3" type="revolute">
        <origin rpy="1.5707963267948966 0 0" xyz="0 -0.316 0" />
        <parent link="panda_link2" />
        <child link="panda_link3" />
        <axis xyz="0 0 1" />
        <limit effort="87.0" lower="-2.8973" upper="2.8973" velocity="2.175" />
        <safety_controller k_position="100.0" k_velocity="40.0" soft_lower_limit="-2.8973" soft_upper_limit="2.8973" />
        <dynamics D="1" K="7000" damping="0.003" friction="0.0" mu_coulomb="0" mu_viscous="16" />
    </joint>
    <!-- sub-link defining detailed meshes for collision with environment -->
    <link name="panda_link4">
        <visual>
            <geometry>
                <mesh filename="package://allegro_hand_description/meshes/visual/link4.dae" />
            </geometry>
        </visual>
        <collision>
            <geometry>
                <mesh filename="package://allegro_hand_description/meshes/collision/link4.stl" />
            </geometry>
        </collision>
        <inertial>
            <mass value="0.1" />
            <origin xyz="0 0 0" rpy="0 0 0" />
            <inertia ixx="0.03" iyy="0.03" izz="0.03" ixy="0.0" ixz="0.0" iyz="0.0" />
        </inertial>
    </link>
    <!-- sub-link defining coarse geometries of real robot's internal self-collision -->
    <link name="panda_link4_sc">
        <collision>
            <origin rpy="0 0 0" xyz="0 0 0" />
            <geometry>
                <cylinder length="0.12" radius="0.09" />
            </geometry>
        </collision>
        <collision>
            <origin xyz="0 0 0.06" />
            <geometry>
                <sphere radius="0.09" />
            </geometry>
        </collision>
        <collision>
            <origin xyz="0 0 -0.06" />
            <geometry>
                <sphere radius="0.09" />
            </geometry>
        </collision>
        <inertial>
            <mass value="0.1" />
            <origin xyz="0 0 0" rpy="0 0 0" />
            <inertia ixx="0.03" iyy="0.03" izz="0.03" ixy="0.0" ixz="0.0" iyz="0.0" />
        </inertial>
    </link>
    <!-- fixed joint between both sub-links -->
    <joint name="panda_link4_sc_joint" type="fixed">
        <origin rpy="0 0 0" />
        <parent link="panda_link4" />
        <child link="panda_link4_sc" />
    </joint>
    <joint name="panda_joint4" type="revolute">
        <origin rpy="1.5707963267948966 0 0" xyz="0.0825 0 0" />
        <parent link="panda_link3" />
        <child link="panda_link4" />
        <axis xyz="0 0 1" />
        <limit effort="87.0" lower="-3.0718" upper="-0.0698" velocity="2.175" />
        <safety_controller k_position="100.0" k_velocity="40.0" soft_lower_limit="-3.0718" soft_upper_limit="-0.0698" />
        <dynamics D="1" K="7000" damping="0.003" friction="0.0" mu_coulomb="0" mu_viscous="16" />
    </joint>
    <!-- sub-link defining detailed meshes for collision with environment -->
    <link name="panda_link5">
        <visual>
            <geometry>
                <mesh filename="package://allegro_hand_description/meshes/visual/link5.dae" />
            </geometry>
        </visual>
        <collision>
            <geometry>
                <mesh filename="package://allegro_hand_description/meshes/collision/link5.stl" />
            </geometry>
        </collision>
        <inertial>
            <mass value="0.1" />
            <origin xyz="0 0 0" rpy="0 0 0" />
            <inertia ixx="0.03" iyy="0.03" izz="0.03" ixy="0.0" ixz="0.0" iyz="0.0" />
        </inertial>
    </link>
    <!-- sub-link defining coarse geometries of real robot's internal self-collision -->
    <link name="panda_link5_sc">
        <collision>
            <origin rpy="0 0 0" xyz="0 0 -0.26" />
            <geometry>
                <cylinder length="0.1" radius="0.09" />
            </geometry>
        </collision>
        <collision>
            <origin xyz="0 0 -0.21000000000000002" />
            <geometry>
                <sphere radius="0.09" />
            </geometry>
        </collision>
        <collision>
            <origin xyz="0 0 -0.31" />
            <geometry>
                <sphere radius="0.09" />
            </geometry>
        </collision>
        <collision>
            <origin rpy="0 0 0.08" xyz="0 0.08 -0.13" />
            <geometry>
                <cylinder length="0.14" radius="0.055" />
            </geometry>
        </collision>
        <collision>
            <origin xyz="0 0.08 -0.06" />
            <geometry>
                <sphere radius="0.055" />
            </geometry>
        </collision>
        <collision>
            <origin xyz="0 0.08 -0.2" />
            <geometry>
                <sphere radius="0.055" />
            </geometry>
        </collision>
        <inertial>
            <mass value="0.1" />
            <origin xyz="0 0 0" rpy="0 0 0" />
            <inertia ixx="0.03" iyy="0.03" izz="0.03" ixy="0.0" ixz="0.0" iyz="0.0" />
        </inertial>
    </link>
    <!-- fixed joint between both sub-links -->
    <joint name="panda_link5_sc_joint" type="fixed">
        <origin rpy="0 0 0" />
        <parent link="panda_link5" />
        <child link="panda_link5_sc" />
    </joint>
    <joint name="panda_joint5" type="revolute">
        <origin rpy="-1.5707963267948966 0 0" xyz="-0.0825 0.384 0" />
        <parent link="panda_link4" />
        <child link="panda_link5" />
        <axis xyz="0 0 1" />
        <limit effort="12.0" lower="-2.8973" upper="2.8973" velocity="2.61" />
        <safety_controller k_position="100.0" k_velocity="40.0" soft_lower_limit="-2.8973" soft_upper_limit="2.8973" />
        <dynamics D="1" K="7000" damping="0.003" friction="0.0" mu_coulomb="0" mu_viscous="16" />
    </joint>
    <!-- sub-link defining detailed meshes for collision with environment -->
    <link name="panda_link6">
        <visual>
            <geometry>
                <mesh filename="package://allegro_hand_description/meshes/visual/link6.dae" />
            </geometry>
        </visual>
        <collision>
            <geometry>
                <mesh filename="package://allegro_hand_description/meshes/collision/link6.stl" />
            </geometry>
        </collision>
        <inertial>
            <mass value="0.1" />
            <origin xyz="0 0 0" rpy="0 0 0" />
            <inertia ixx="0.03" iyy="0.03" izz="0.03" ixy="0.0" ixz="0.0" iyz="0.0" />
        </inertial>
    </link>
    <!-- sub-link defining coarse geometries of real robot's internal self-collision -->
    <link name="panda_link6_sc">
        <collision>
            <origin rpy="0 0 0" xyz="0 0 -0.03" />
            <geometry>
                <cylinder length="0.08" radius="0.08" />
            </geometry>
        </collision>
        <collision>
            <origin xyz="0 0 0.010000000000000002" />
            <geometry>
                <sphere radius="0.08" />
            </geometry>
        </collision>
        <collision>
            <origin xyz="0 0 -0.07" />
            <geometry>
                <sphere radius="0.08" />
            </geometry>
        </collision>
        <inertial>
            <mass value="0.1" />
            <origin xyz="0 0 0" rpy="0 0 0" />
            <inertia ixx="0.03" iyy="0.03" izz="0.03" ixy="0.0" ixz="0.0" iyz="0.0" />
        </inertial>
    </link>
    <!-- fixed joint between both sub-links -->
    <joint name="panda_link6_sc_joint" type="fixed">
        <origin rpy="0 0 0" />
        <parent link="panda_link6" />
        <child link="panda_link6_sc" />
    </joint>
    <joint name="panda_joint6" type="revolute">
        <origin rpy="1.5707963267948966 -0.7853981633974483 0" xyz="0 0.0 0" />
        <parent link="panda_link5" />
        <child link="panda_link6" />
        <axis xyz="0 0 1" />
        <limit effort="12.0" lower="-0.0175" upper="3.7525" velocity="2.61" />
        <safety_controller k_position="100.0" k_velocity="40.0" soft_lower_limit="-0.0175" soft_upper_limit="3.7525" />
        <dynamics D="1" K="7000" damping="0.003" friction="0.0" mu_coulomb="0" mu_viscous="16" />
    </joint>
    <!-- sub-link defining detailed meshes for collision with environment -->
    <link name="panda_link7">
        <visual>
            <geometry>
                <mesh filename="package://allegro_hand_description/meshes/visual/link7.dae" />
            </geometry>
        </visual>
        <collision>
            <geometry>
                <mesh filename="package://allegro_hand_description/meshes/collision/link7.stl" />
            </geometry>
        </collision>
        <inertial>
            <mass value="0.1" />
            <origin xyz="0 0 0" rpy="0 0 0" />
            <inertia ixx="0.03" iyy="0.03" izz="0.03" ixy="0.0" ixz="0.0" iyz="0.0" />
        </inertial>
    </link>
    <!-- sub-link defining coarse geometries of real robot's internal self-collision -->
    <link name="panda_link7_sc">
        <collision>
            <origin rpy="0 0 0" xyz="0 0 0.01" />
            <geometry>
                <cylinder length="0.14" radius="0.07" />
            </geometry>
        </collision>
        <collision>
            <origin xyz="0 0 0.08" />
            <geometry>
                <sphere radius="0.07" />
            </geometry>
        </collision>
        <collision>
            <origin xyz="0 0 -0.060000000000000005" />
            <geometry>
                <sphere radius="0.07" />
            </geometry>
        </collision>
        <collision>
            <origin rpy="0 1.5707963267948966 0" xyz="0.06 0 0.082" />
            <geometry>
                <cylinder length="0.01" radius="0.06" />
            </geometry>
        </collision>
        <collision>
            <origin xyz="0.065 0 0.082" />
            <geometry>
                <sphere radius="0.06" />
            </geometry>
        </collision>
        <collision>
            <origin xyz="0.055 0 0.082" />
            <geometry>
                <sphere radius="0.06" />
            </geometry>
        </collision>
        <inertial>
            <mass value="0.1" />
            <origin xyz="0 0 0" rpy="0 0 0" />
            <inertia ixx="0.03" iyy="0.03" izz="0.03" ixy="0.0" ixz="0.0" iyz="0.0" />
        </inertial>
    </link>
    <!-- fixed joint between both sub-links -->
    <joint name="panda_link7_sc_joint" type="fixed">
        <origin rpy="0 0 0.7853981633974483" />
        <parent link="panda_link7" />
        <child link="panda_link7_sc" />
    </joint>
    <joint name="panda_joint7" type="revolute">
        <origin rpy="1.5707963267948966 0 0" xyz="0.088 0 0" />
        <parent link="panda_link6" />
        <child link="panda_link7" />
        <axis xyz="0 0 1" />
        <limit effort="12.0" lower="-2.8973" upper="2.8973" velocity="2.61" />
        <safety_controller k_position="100.0" k_velocity="40.0" soft_lower_limit="-2.8973" soft_upper_limit="2.8973" />
        <dynamics D="1" K="7000" damping="0.003" friction="0.0" mu_coulomb="0" mu_viscous="16" />
    </joint>
    <link name="panda_link8" />
    <joint name="panda_joint8" type="fixed">
        <origin rpy="0 0 0" xyz="0 0 0.107" />
        <parent link="panda_link7" />
        <child link="panda_link8" />
    </joint>
    <!--
rosrun xacro xacro.py allegro_hand_description_right.urdf.xacro > allegro_hand_description_right.urdf
roslaunch launchers/fuerte/allegro_hand_jgui_right_virtual.launch 
-->
    <!-- ======================== MOVE PARAMS FOR PANDA========================= -->
    <!-- ======================== BASE PARAMS ========================= -->
    <!-- ======================== FINGER PARAMS ======================== -->
    <!--0.002298-->
    <!-- ========================= THUMB PARAMS ========================= -->
    <!-- ========================= LIMITS ========================= -->
    <joint name="allegro_hand_joint" type="fixed">
        <parent link="panda_link8" />
        <!-- <parent link=' ' /> -->
        <child link="base_link" />
        <origin rpy="0 0 0" xyz="0 0 0" />
    </joint>
    <link name="base_link">
        <visual>
            <geometry>
                <mesh filename="package://allegro_hand_description/meshes/base_link_left.STL" />
            </geometry>
            <!-- LEFT -->
            <origin rpy="-1.5707963259 0 0" xyz="0 0 0.09 " />
            <!-- RIGHT -->
            <!--<origin rpy="0 0 0" xyz="0 0 0 "/>-->
            <material name="black">
                <color rgba="0.2 0.2 0.2 1" />
            </material>
        </visual>
        <collision>
            <origin rpy="0 0 0" xyz="-0.009300 0 0.042499999999999996" />
            <geometry>
                <box size="0.0408 0.1130 0.095" />
            </geometry>
        </collision>
        <inertial>
            <mass value="0.1" />
            <origin xyz="0 0 0" rpy="0 0 0" />
            <inertia ixx="0.03" iyy="0.03" izz="0.03" ixy="0.0" ixz="0.0" iyz="0.0" />
        </inertial>
    </link>
    <!-- ============================================================================= -->
    <!-- ============================================================================= -->
    <!-- ============================================================================= -->
    <!-- ============================================================================= -->
    <!-- END THUMB MACRO -->
    <!-- [[END]] THREE FINGER MACRO -->
    <!-- FINGERS -->
    <!-- [LINK 0, 4, 8] -->
    <link name="link_8">
        <visual>
            <geometry>
                <mesh filename="package://allegro_hand_description/meshes/link_0.0.STL" />
            </geometry>
            <material name="black" />
        </visual>
        <collision>
            <geometry>
                <box size="0.0196 0.0275 0.0164" />
            </geometry>
            <origin rpy="0 0 0" xyz="0 0 0.0982" />
        </collision>
        <inertial>
            <mass value="0.1" />
            <origin xyz="0 0 0" rpy="0 0 0" />
            <inertia ixx="0.03" iyy="0.03" izz="0.03" ixy="0.0" ixz="0.0" iyz="0.0" />
        </inertial>
    </link>
    <joint name="joint_8" type="revolute">
        <axis xyz="0 0 1" />
        <limit effort="0" lower="-0.47" upper="0.47" velocity="0" />
        <parent link="base_link" />
        <child link="link_8" />
        <origin rpy="-0.08726646254999999 0 0" xyz="0 0.0435 0.088458" />
    </joint>
    <!-- [LINK 1, 5, 9] -->
    <link name="link_9">
        <visual>
            <geometry>
                <mesh filename="package://allegro_hand_description/meshes/link_1.0.STL" />
            </geometry>
            <material name="black" />
        </visual>
        <collision>
            <geometry>
                <box size="0.0196 0.0275 0.054" />
            </geometry>
            <origin rpy="0 0 0" xyz="0 0 0.027" />
        </collision>
        <inertial>
            <mass value="0.1" />
            <origin xyz="0 0 0" rpy="0 0 0" />
            <inertia ixx="0.03" iyy="0.03" izz="0.03" ixy="0.0" ixz="0.0" iyz="0.0" />
        </inertial>
    </link>
    <joint name="joint_9" type="revolute">
        <limit effort="0" lower="-0.19599999999999998" upper="1.6099999999999999" velocity="0" />
        <axis xyz="0 1 0" />
        <parent link="link_8" />
        <child link="link_9" />
        <origin xyz="0 0 0.0164" />
    </joint>
    <!-- [LINK 2, 6, 10]-->
    <link name="link_10">
        <visual>
            <geometry>
                <mesh filename="package://allegro_hand_description/meshes/link_2.0.STL" />
            </geometry>
            <material name="black" />
        </visual>
        <collision>
            <geometry>
                <box size="0.0196 0.0275 0.0384" />
            </geometry>
            <origin rpy="0 0 0" xyz="0 0 0.0192" />
        </collision>
        <inertial>
            <mass value="0.1" />
            <origin xyz="0 0 0" rpy="0 0 0" />
            <inertia ixx="0.03" iyy="0.03" izz="0.03" ixy="0.0" ixz="0.0" iyz="0.0" />
        </inertial>
    </link>
    <joint name="joint_10" type="revolute">
        <axis xyz="0 1 0" />
        <limit effort="0" lower="-0.17400000000000002" upper="1.7089999999999999" velocity="0" />
        <parent link="link_9" />
        <child link="link_10" />
        <origin xyz="0 0 0.054" />
    </joint>
    <!-- [LINK 3, 7, 11] -->
    <link name="link_11">
        <visual>
            <geometry>
                <mesh filename="package://allegro_hand_description/meshes/link_3.0.STL" />
            </geometry>
            <material name="black" />
        </visual>
        <collision>
            <geometry>
                <box size="0.0196 0.0275 0.026699999999999998" />
            </geometry>
            <origin rpy="0 0 0" xyz="0 0 0.013349999999999999" />
        </collision>
        <inertial>
            <mass value="0.1" />
            <origin xyz="0 0 0" rpy="0 0 0" />
            <inertia ixx="0.03" iyy="0.03" izz="0.03" ixy="0.0" ixz="0.0" iyz="0.0" />
        </inertial>
    </link>
    <joint name="joint_11" type="revolute">
        <axis xyz="0 1 0" />
        <limit effort="0" lower="-0.227" upper="1.6179999999999999" velocity="0" />
        <parent link="link_10" />
        <child link="link_11" />
        <origin xyz="0 0 0.0384" />
    </joint>
    <!-- [FINGER TIP] -->
    <link name="link_11_tip">
        <visual>
            <geometry>
                <mesh filename="package://allegro_hand_description/meshes/link_3.0_tip.STL" />
            </geometry>
            <material name="white">
                <color rgba=".9 .9 .9 1" />
            </material>
        </visual>
        <collision>
            <geometry>
                <sphere radius="0.012" />
            </geometry>
        </collision>
        <inertial>
            <mass value="0.1" />
            <origin xyz="0 0 0" rpy="0 0 0" />
            <inertia ixx="0.03" iyy="0.03" izz="0.03" ixy="0.0" ixz="0.0" iyz="0.0" />
        </inertial>
    </link>
    <joint name="joint_11_tip" type="fixed">
        <parent link="link_11" />
        <child link="link_11_tip" />
        <origin rpy="0 0 0" xyz="0 0 0.026699999999999998" />
    </joint>
    <!-- [LINK 0, 4, 8] -->
    <link name="link_4">
        <visual>
            <geometry>
                <mesh filename="package://allegro_hand_description/meshes/link_0.0.STL" />
            </geometry>
            <material name="black" />
        </visual>
        <collision>
            <geometry>
                <box size="0.0196 0.0275 0.0164" />
            </geometry>
            <origin rpy="0 0 0" xyz="0 0 0.0982" />
        </collision>
        <inertial>
            <mass value="0.1" />
            <origin xyz="0 0 0" rpy="0 0 0" />
            <inertia ixx="0.03" iyy="0.03" izz="0.03" ixy="0.0" ixz="0.0" iyz="0.0" />
        </inertial>
    </link>
    <joint name="joint_4" type="revolute">
        <axis xyz="0 0 1" />
        <limit effort="0" lower="-0.47" upper="0.47" velocity="0" />
        <parent link="base_link" />
        <child link="link_4" />
        <origin rpy="0.0 0 0" xyz="0 0 0.0907" />
    </joint>
    <!-- [LINK 1, 5, 9] -->
    <link name="link_5">
        <visual>
            <geometry>
                <mesh filename="package://allegro_hand_description/meshes/link_1.0.STL" />
            </geometry>
            <material name="black" />
        </visual>
        <collision>
            <geometry>
                <box size="0.0196 0.0275 0.054" />
            </geometry>
            <origin rpy="0 0 0" xyz="0 0 0.027" />
        </collision>
        <inertial>
            <mass value="0.1" />
            <origin xyz="0 0 0" rpy="0 0 0" />
            <inertia ixx="0.03" iyy="0.03" izz="0.03" ixy="0.0" ixz="0.0" iyz="0.0" />
        </inertial>
    </link>
    <joint name="joint_5" type="revolute">
        <limit effort="0" lower="-0.19599999999999998" upper="1.6099999999999999" velocity="0" />
        <axis xyz="0 1 0" />
        <parent link="link_4" />
        <child link="link_5" />
        <origin xyz="0 0 0.0164" />
    </joint>
    <!-- [LINK 2, 6, 10]-->
    <link name="link_6">
        <visual>
            <geometry>
                <mesh filename="package://allegro_hand_description/meshes/link_2.0.STL" />
            </geometry>
            <material name="black" />
        </visual>
        <collision>
            <geometry>
                <box size="0.0196 0.0275 0.0384" />
            </geometry>
            <origin rpy="0 0 0" xyz="0 0 0.0192" />
        </collision>
        <inertial>
            <mass value="0.1" />
            <origin xyz="0 0 0" rpy="0 0 0" />
            <inertia ixx="0.03" iyy="0.03" izz="0.03" ixy="0.0" ixz="0.0" iyz="0.0" />
        </inertial>
    </link>
    <joint name="joint_6" type="revolute">
        <axis xyz="0 1 0" />
        <limit effort="0" lower="-0.17400000000000002" upper="1.7089999999999999" velocity="0" />
        <parent link="link_5" />
        <child link="link_6" />
        <origin xyz="0 0 0.054" />
    </joint>
    <!-- [LINK 3, 7, 11] -->
    <link name="link_7">
        <visual>
            <geometry>
                <mesh filename="package://allegro_hand_description/meshes/link_3.0.STL" />
            </geometry>
            <material name="black" />
        </visual>
        <collision>
            <geometry>
                <box size="0.0196 0.0275 0.026699999999999998" />
            </geometry>
            <origin rpy="0 0 0" xyz="0 0 0.013349999999999999" />
        </collision>
        <inertial>
            <mass value="0.1" />
            <origin xyz="0 0 0" rpy="0 0 0" />
            <inertia ixx="0.03" iyy="0.03" izz="0.03" ixy="0.0" ixz="0.0" iyz="0.0" />
        </inertial>
    </link>
    <joint name="joint_7" type="revolute">
        <axis xyz="0 1 0" />
        <limit effort="0" lower="-0.227" upper="1.6179999999999999" velocity="0" />
        <parent link="link_6" />
        <child link="link_7" />
        <origin xyz="0 0 0.0384" />
    </joint>
    <!-- [FINGER TIP] -->
    <link name="link_7_tip">
        <visual>
            <geometry>
                <mesh filename="package://allegro_hand_description/meshes/link_3.0_tip.STL" />
            </geometry>
            <material name="white">
                <color rgba=".9 .9 .9 1" />
            </material>
        </visual>
        <collision>
            <geometry>
                <sphere radius="0.012" />
            </geometry>
        </collision>
        <inertial>
            <mass value="0.1" />
            <origin xyz="0 0 0" rpy="0 0 0" />
            <inertia ixx="0.03" iyy="0.03" izz="0.03" ixy="0.0" ixz="0.0" iyz="0.0" />
        </inertial>
    </link>
    <joint name="joint_7_tip" type="fixed">
        <parent link="link_7" />
        <child link="link_7_tip" />
        <origin rpy="0 0 0" xyz="0 0 0.026699999999999998" />
    </joint>
    <!-- [LINK 0, 4, 8] -->
    <link name="link_0">
        <visual>
            <geometry>
                <mesh filename="package://allegro_hand_description/meshes/link_0.0.STL" />
            </geometry>
            <material name="black" />
        </visual>
        <collision>
            <geometry>
                <box size="0.0196 0.0275 0.0164" />
            </geometry>
            <origin rpy="0 0 0" xyz="0 0 0.0982" />
        </collision>
        <inertial>
            <mass value="0.1" />
            <origin xyz="0 0 0" rpy="0 0 0" />
            <inertia ixx="0.03" iyy="0.03" izz="0.03" ixy="0.0" ixz="0.0" iyz="0.0" />
        </inertial>
    </link>
    <joint name="joint_0" type="revolute">
        <axis xyz="0 0 1" />
        <limit effort="0" lower="-0.47" upper="0.47" velocity="0" />
        <parent link="base_link" />
        <child link="link_0" />
        <origin rpy="0.08726646254999999 0 0" xyz="0 -0.0435 0.088458" />
    </joint>
    <!-- [LINK 1, 5, 9] -->
    <link name="link_1">
        <visual>
            <geometry>
                <mesh filename="package://allegro_hand_description/meshes/link_1.0.STL" />
            </geometry>
            <material name="black" />
        </visual>
        <collision>
            <geometry>
                <box size="0.0196 0.0275 0.054" />
            </geometry>
            <origin rpy="0 0 0" xyz="0 0 0.027" />
        </collision>
        <inertial>
            <mass value="0.1" />
            <origin xyz="0 0 0" rpy="0 0 0" />
            <inertia ixx="0.03" iyy="0.03" izz="0.03" ixy="0.0" ixz="0.0" iyz="0.0" />
        </inertial>
    </link>
    <joint name="joint_1" type="revolute">
        <limit effort="0" lower="-0.19599999999999998" upper="1.6099999999999999" velocity="0" />
        <axis xyz="0 1 0" />
        <parent link="link_0" />
        <child link="link_1" />
        <origin xyz="0 0 0.0164" />
    </joint>
    <!-- [LINK 2, 6, 10]-->
    <link name="link_2">
        <visual>
            <geometry>
                <mesh filename="package://allegro_hand_description/meshes/link_2.0.STL" />
            </geometry>
            <material name="black" />
        </visual>
        <collision>
            <geometry>
                <box size="0.0196 0.0275 0.0384" />
            </geometry>
            <origin rpy="0 0 0" xyz="0 0 0.0192" />
        </collision>
        <inertial>
            <mass value="0.1" />
            <origin xyz="0 0 0" rpy="0 0 0" />
            <inertia ixx="0.03" iyy="0.03" izz="0.03" ixy="0.0" ixz="0.0" iyz="0.0" />
        </inertial>
    </link>
    <joint name="joint_2" type="revolute">
        <axis xyz="0 1 0" />
        <limit effort="0" lower="-0.17400000000000002" upper="1.7089999999999999" velocity="0" />
        <parent link="link_1" />
        <child link="link_2" />
        <origin xyz="0 0 0.054" />
    </joint>
    <!-- [LINK 3, 7, 11] -->
    <link name="link_3">
        <visual>
            <geometry>
                <mesh filename="package://allegro_hand_description/meshes/link_3.0.STL" />
            </geometry>
            <material name="black" />
        </visual>
        <collision>
            <geometry>
                <box size="0.0196 0.0275 0.026699999999999998" />
            </geometry>
            <origin rpy="0 0 0" xyz="0 0 0.013349999999999999" />
        </collision>
        <inertial>
            <mass value="0.1" />
            <origin xyz="0 0 0" rpy="0 0 0" />
            <inertia ixx="0.03" iyy="0.03" izz="0.03" ixy="0.0" ixz="0.0" iyz="0.0" />
        </inertial>
    </link>
    <joint name="joint_3" type="revolute">
        <axis xyz="0 1 0" />
        <limit effort="0" lower="-0.227" upper="1.6179999999999999" velocity="0" />
        <parent link="link_2" />
        <child link="link_3" />
        <origin xyz="0 0 0.0384" />
    </joint>
    <!-- [FINGER TIP] -->
    <link name="link_3_tip">
        <visual>
            <geometry>
                <mesh filename="package://allegro_hand_description/meshes/link_3.0_tip.STL" />
            </geometry>
            <material name="white">
                <color rgba=".9 .9 .9 1" />
            </material>
        </visual>
        <collision>
            <geometry>
                <sphere radius="0.012" />
            </geometry>
        </collision>
        <inertial>
            <mass value="0.1" />
            <origin xyz="0 0 0" rpy="0 0 0" />
            <inertia ixx="0.03" iyy="0.03" izz="0.03" ixy="0.0" ixz="0.0" iyz="0.0" />
        </inertial>
    </link>
    <joint name="joint_3_tip" type="fixed">
        <parent link="link_3" />
        <child link="link_3_tip" />
        <origin rpy="0 0 0" xyz="0 0 0.026699999999999998" />
    </joint>
    <!-- THUMB -->
    <!--
<xacro:thumb_right
	finger_num=			"3" 
	offset_origin_x=	"-0.0182"	
	offset_origin_y=	"0.019333" 
	offset_origin_z=	"-0.045987"
	
	
	finger_angle_r=		"0"
	finger_angle_p=		"-${95*DEG2RAD}"	
	finger_angle_y=		"-${90*DEG2RAD}"
/>
-->
    <!-- [LINK 12] -->
    <link name="link_12">
        <visual>
            <geometry>
                <!-- RIGHT -->
                <!-- <mesh filename="package://allegro_hand_description/meshes/link_12.0_right.STL" /> -->
                <!-- LEFT -->
                <mesh filename="package://allegro_hand_description/meshes/link_12.0_left.STL" />
            </geometry>
            <material name="black">
                <color rgba=".2 .2 .2 1" />
            </material>
            <origin rpy="3.1415926518 0 0" xyz="0 0 0.0145" />
        </visual>
        <collision>
            <geometry>
                <box size="0.0358 0.034 0.0455" />
            </geometry>
            <!-- RIGHT -->
            <!-- <origin rpy="0 0 0" xyz="${-0.0358/2+0.0} ${.018/2} ${.029/2}"/> -->
            <!-- LEFT -->
            <origin rpy="0 0 0" xyz="-0.0179 -0.009 0.0145" />
        </collision>
        <inertial>
            <mass value="0.1" />
            <origin xyz="0 0 0" rpy="0 0 0" />
            <inertia ixx="0.03" iyy="0.03" izz="0.03" ixy="0.0" ixz="0.0" iyz="0.0" />
        </inertial>
    </link>
    <joint name="joint_12" type="revolute">
        <axis xyz="+1 0 0" />
        <limit effort="0" lower="0.263" upper="1.396" velocity="0" />
        <parent link="base_link" />
        <child link="link_12" />
        <origin rpy="0 -1.6580627884499999 1.5707963259" xyz="-0.0182 -0.019333 0.044013" />
    </joint>
    <!-- [LINK 13] -->
    <link name="link_13">
        <visual>
            <geometry>
                <mesh filename="package://allegro_hand_description/meshes/link_13.0.STL" />
            </geometry>
            <material name="black">
                <color rgba=".2 .2 .2 1" />
            </material>
        </visual>
        <collision>
            <geometry>
                <box size="0.0196 0.0275 0.0177" />
            </geometry>
            <origin rpy="0 0 0" xyz="0 0 0.00885" />
        </collision>
        <inertial>
            <mass value="0.1" />
            <origin xyz="0 0 0" rpy="0 0 0" />
            <inertia ixx="0.03" iyy="0.03" izz="0.03" ixy="0.0" ixz="0.0" iyz="0.0" />
        </inertial>
    </link>
    <joint name="joint_13" type="revolute">
        <axis xyz="0 0 -1" />
        <limit effort="0" lower="-0.10499999999999998" upper="1.1629999999999998" velocity="0" />
        <parent link="link_12" />
        <child link="link_13" />
        <!-- RIGHT -->
        <!-- <origin xyz="-0.027 0.005 0.0399"/> -->
        <!-- LEFT -->
        <origin xyz="-0.027 -0.005 0.0399" />
    </joint>
    <!-- [LINK 14] -->
    <link name="link_14">
        <visual>
            <geometry>
                <mesh filename="package://allegro_hand_description/meshes/link_14.0.STL" />
            </geometry>
            <material name="black" />
        </visual>
        <collision>
            <geometry>
                <box size="0.0196 0.0275 0.0514" />
            </geometry>
            <origin rpy="0 0 0" xyz="0 0 0.0257" />
        </collision>
        <inertial>
            <mass value="0.1" />
            <origin xyz="0 0 0" rpy="0 0 0" />
            <inertia ixx="0.03" iyy="0.03" izz="0.03" ixy="0.0" ixz="0.0" iyz="0.0" />
        </inertial>
    </link>
    <joint name="joint_14" type="revolute">
        <axis xyz="0 1 0" />
        <limit effort="0" lower="-0.18899999999999997" upper="1.644" velocity="0" />
        <parent link="link_13" />
        <child link="link_14" />
        <origin xyz="0 0 0.0177" />
    </joint>
    <!-- [LINK 15] -->
    <link name="link_15">
        <visual>
            <geometry>
                <mesh filename="package://allegro_hand_description/meshes/link_15.0.STL" />
            </geometry>
            <material name="black" />
        </visual>
        <collision>
            <geometry>
                <box size="0.0196 0.0275 0.042300000000000004" />
            </geometry>
            <origin rpy="0 0 0" xyz="0 0 0.021150000000000002" />
        </collision>
        <inertial>
            <mass value="0.1" />
            <origin xyz="0 0 0" rpy="0 0 0" />
            <inertia ixx="0.03" iyy="0.03" izz="0.03" ixy="0.0" ixz="0.0" iyz="0.0" />
        </inertial>
    </link>
    <joint name="joint_15" type="revolute">
        <axis xyz="0 1 0" />
        <limit effort="0" lower="-0.162" upper="1.7189999999999999" velocity="0" />
        <parent link="link_14" />
        <child link="link_15" />
        <origin xyz="0 0 0.0514" />
    </joint>
    <!-- [FINGER TIP] -->
    <link name="link_15_tip">
        <visual>
            <geometry>
                <mesh filename="package://allegro_hand_description/meshes/link_15.0_tip.STL" />
            </geometry>
            <material name="white">
                <color rgba=".9 .9 .9 1" />
            </material>
        </visual>
        <collision>
            <geometry>
                <sphere radius="0.012" />
            </geometry>
            <origin rpy="0 0 0" xyz="0 0 0" />
        </collision>
        <inertial>
            <mass value="0.1" />
            <origin xyz="0 0 0" rpy="0 0 0" />
            <inertia ixx="0.03" iyy="0.03" izz="0.03" ixy="0.0" ixz="0.0" iyz="0.0" />
        </inertial>
    </link>
    <joint name="joint_15_tip" type="fixed">
        <parent link="link_15" />
        <child link="link_15_tip" />
        <origin rpy="0 0 0" xyz="0 0 0.042300000000000004" />
        <!--0.0267000000000005-->
    </joint>
    <transmission name="trans_panda_joint1">
        <type>transmission_interface/SimpleTransmission</type>
        <joint name="panda_joint1">
            <hardwareInterface>hardware_interface/PositionJointInterface</hardwareInterface>
        </joint>
        <actuator name="panda_joint1_motor">
            <hardwareInterface>hardware_interface/PositionJointInterface</hardwareInterface>
            <mechanicalReduction>1</mechanicalReduction>
        </actuator>
    </transmission>
    <transmission name="trans_panda_joint2">
        <type>transmission_interface/SimpleTransmission</type>
        <joint name="panda_joint2">
            <hardwareInterface>hardware_interface/PositionJointInterface</hardwareInterface>
        </joint>
        <actuator name="panda_joint2_motor">
            <hardwareInterface>hardware_interface/PositionJointInterface</hardwareInterface>
            <mechanicalReduction>1</mechanicalReduction>
        </actuator>
    </transmission>
    <transmission name="trans_panda_joint3">
        <type>transmission_interface/SimpleTransmission</type>
        <joint name="panda_joint3">
            <hardwareInterface>hardware_interface/PositionJointInterface</hardwareInterface>
        </joint>
        <actuator name="panda_joint3_motor">
            <hardwareInterface>hardware_interface/PositionJointInterface</hardwareInterface>
            <mechanicalReduction>1</mechanicalReduction>
        </actuator>
    </transmission>
    <transmission name="trans_panda_joint4">
        <type>transmission_interface/SimpleTransmission</type>
        <joint name="panda_joint4">
            <hardwareInterface>hardware_interface/PositionJointInterface</hardwareInterface>
        </joint>
        <actuator name="panda_joint4_motor">
            <hardwareInterface>hardware_interface/PositionJointInterface</hardwareInterface>
            <mechanicalReduction>1</mechanicalReduction>
        </actuator>
    </transmission>
    <transmission name="trans_panda_joint5">
        <type>transmission_interface/SimpleTransmission</type>
        <joint name="panda_joint5">
            <hardwareInterface>hardware_interface/PositionJointInterface</hardwareInterface>
        </joint>
        <actuator name="panda_joint5_motor">
            <hardwareInterface>hardware_interface/PositionJointInterface</hardwareInterface>
            <mechanicalReduction>1</mechanicalReduction>
        </actuator>
    </transmission>
    <transmission name="trans_panda_joint6">
        <type>transmission_interface/SimpleTransmission</type>
        <joint name="panda_joint6">
            <hardwareInterface>hardware_interface/PositionJointInterface</hardwareInterface>
        </joint>
        <actuator name="panda_joint6_motor">
            <hardwareInterface>hardware_interface/PositionJointInterface</hardwareInterface>
            <mechanicalReduction>1</mechanicalReduction>
        </actuator>
    </transmission>
    <transmission name="trans_panda_joint7">
        <type>transmission_interface/SimpleTransmission</type>
        <joint name="panda_joint7">
            <hardwareInterface>hardware_interface/PositionJointInterface</hardwareInterface>
        </joint>
        <actuator name="panda_joint7_motor">
            <hardwareInterface>hardware_interface/PositionJointInterface</hardwareInterface>
            <mechanicalReduction>1</mechanicalReduction>
        </actuator>
    </transmission>
    <transmission name="trans_joint_8">
        <type>transmission_interface/SimpleTransmission</type>
        <joint name="joint_8">
            <hardwareInterface>hardware_interface/EffortJointInterface</hardwareInterface>
        </joint>
        <actuator name="joint_8_motor">
            <hardwareInterface>hardware_interface/EffortJointInterface</hardwareInterface>
            <mechanicalReduction>1</mechanicalReduction>
        </actuator>
    </transmission>
    <transmission name="trans_joint_9">
        <type>transmission_interface/SimpleTransmission</type>
        <joint name="joint_9">
            <hardwareInterface>hardware_interface/EffortJointInterface</hardwareInterface>
        </joint>
        <actuator name="joint_9_motor">
            <hardwareInterface>hardware_interface/EffortJointInterface</hardwareInterface>
            <mechanicalReduction>1</mechanicalReduction>
        </actuator>
    </transmission>
    <transmission name="trans_joint_10">
        <type>transmission_interface/SimpleTransmission</type>
        <joint name="joint_10">
            <hardwareInterface>hardware_interface/EffortJointInterface</hardwareInterface>
        </joint>
        <actuator name="joint_10_motor">
            <hardwareInterface>hardware_interface/EffortJointInterface</hardwareInterface>
            <mechanicalReduction>1</mechanicalReduction>
        </actuator>
    </transmission>
    <transmission name="trans_joint_11">
        <type>transmission_interface/SimpleTransmission</type>
        <joint name="joint_11">
            <hardwareInterface>hardware_interface/EffortJointInterface</hardwareInterface>
        </joint>
        <actuator name="joint_11_motor">
            <hardwareInterface>hardware_interface/EffortJointInterface</hardwareInterface>
            <mechanicalReduction>1</mechanicalReduction>
        </actuator>
    </transmission>
    <transmission name="trans_joint_4">
        <type>transmission_interface/SimpleTransmission</type>
        <joint name="joint_4">
            <hardwareInterface>hardware_interface/EffortJointInterface</hardwareInterface>
        </joint>
        <actuator name="joint_4_motor">
            <hardwareInterface>hardware_interface/EffortJointInterface</hardwareInterface>
            <mechanicalReduction>1</mechanicalReduction>
        </actuator>
    </transmission>
    <transmission name="trans_joint_5">
        <type>transmission_interface/SimpleTransmission</type>
        <joint name="joint_5">
            <hardwareInterface>hardware_interface/EffortJointInterface</hardwareInterface>
        </joint>
        <actuator name="joint_5_motor">
            <hardwareInterface>hardware_interface/EffortJointInterface</hardwareInterface>
            <mechanicalReduction>1</mechanicalReduction>
        </actuator>
    </transmission>
    <transmission name="trans_joint_6">
        <type>transmission_interface/SimpleTransmission</type>
        <joint name="joint_6">
            <hardwareInterface>hardware_interface/EffortJointInterface</hardwareInterface>
        </joint>
        <actuator name="joint_6_motor">
            <hardwareInterface>hardware_interface/EffortJointInterface</hardwareInterface>
            <mechanicalReduction>1</mechanicalReduction>
        </actuator>
    </transmission>
    <transmission name="trans_joint_7">
        <type>transmission_interface/SimpleTransmission</type>
        <joint name="joint_7">
            <hardwareInterface>hardware_interface/EffortJointInterface</hardwareInterface>
        </joint>
        <actuator name="joint_7_motor">
            <hardwareInterface>hardware_interface/EffortJointInterface</hardwareInterface>
            <mechanicalReduction>1</mechanicalReduction>
        </actuator>
    </transmission>
    <transmission name="trans_joint_0">
        <type>transmission_interface/SimpleTransmission</type>
        <joint name="joint_0">
            <hardwareInterface>hardware_interface/EffortJointInterface</hardwareInterface>
        </joint>
        <actuator name="joint_0_motor">
            <hardwareInterface>hardware_interface/EffortJointInterface</hardwareInterface>
            <mechanicalReduction>1</mechanicalReduction>
        </actuator>
    </transmission>
    <transmission name="trans_joint_1">
        <type>transmission_interface/SimpleTransmission</type>
        <joint name="joint_1">
            <hardwareInterface>hardware_interface/EffortJointInterface</hardwareInterface>
        </joint>
        <actuator name="joint_1_motor">
            <hardwareInterface>hardware_interface/EffortJointInterface</hardwareInterface>
            <mechanicalReduction>1</mechanicalReduction>
        </actuator>
    </transmission>
    <transmission name="trans_joint_2">
        <type>transmission_interface/SimpleTransmission</type>
        <joint name="joint_2">
            <hardwareInterface>hardware_interface/EffortJointInterface</hardwareInterface>
        </joint>
        <actuator name="joint_2_motor">
            <hardwareInterface>hardware_interface/EffortJointInterface</hardwareInterface>
            <mechanicalReduction>1</mechanicalReduction>
        </actuator>
    </transmission>
    <transmission name="trans_joint_3">
        <type>transmission_interface/SimpleTransmission</type>
        <joint name="joint_3">
            <hardwareInterface>hardware_interface/EffortJointInterface</hardwareInterface>
        </joint>
        <actuator name="joint_3_motor">
            <hardwareInterface>hardware_interface/EffortJointInterface</hardwareInterface>
            <mechanicalReduction>1</mechanicalReduction>
        </actuator>
    </transmission>
    <transmission name="trans_joint_12">
        <type>transmission_interface/SimpleTransmission</type>
        <joint name="joint_12">
            <hardwareInterface>hardware_interface/EffortJointInterface</hardwareInterface>
        </joint>
        <actuator name="joint_12_motor">
            <hardwareInterface>hardware_interface/EffortJointInterface</hardwareInterface>
            <mechanicalReduction>1</mechanicalReduction>
        </actuator>
    </transmission>
    <transmission name="trans_joint_13">
        <type>transmission_interface/SimpleTransmission</type>
        <joint name="joint_13">
            <hardwareInterface>hardware_interface/EffortJointInterface</hardwareInterface>
        </joint>
        <actuator name="joint_13_motor">
            <hardwareInterface>hardware_interface/EffortJointInterface</hardwareInterface>
            <mechanicalReduction>1</mechanicalReduction>
        </actuator>
    </transmission>
    <transmission name="trans_joint_14">
        <type>transmission_interface/SimpleTransmission</type>
        <joint name="joint_14">
            <hardwareInterface>hardware_interface/EffortJointInterface</hardwareInterface>
        </joint>
        <actuator name="joint_14_motor">
            <hardwareInterface>hardware_interface/EffortJointInterface</hardwareInterface>
            <mechanicalReduction>1</mechanicalReduction>
        </actuator>
    </transmission>
    <transmission name="trans_joint_15">
        <type>transmission_interface/SimpleTransmission</type>
        <joint name="joint_15">
            <hardwareInterface>hardware_interface/EffortJointInterface</hardwareInterface>
        </joint>
        <actuator name="joint_15_motor">
            <hardwareInterface>hardware_interface/EffortJointInterface</hardwareInterface>
            <mechanicalReduction>1</mechanicalReduction>
        </actuator>
    </transmission>
    <gazebo>
        <plugin name="gazebo_ros_control" filename="libgazebo_ros_control.so">
            <robotNamespace>/</robotNamespace>
        </plugin>
    </gazebo>
</robot>

